File: Design_Project-Carbon_Fiber_Rim/Manufacturing/Material Testing/Day 1/number1.is_tens_RawData/Specimen_RawData_1.csv
Time,Extension,Tensile strain (Clip on Extensometer),Clip on Extensometer,Load
(s),(mm),(mm/mm),(mm/mm),(kN)
"0.00000","0.03881","-0.00073","-0.00073","0.10442"
"0.30000","0.06623","-0.00068","-0.00068","0.23597"
"0.60000","0.09076","-0.00059","-0.00059","0.33023"
"0.90000","0.11544","-0.00049","-0.00049","0.41348"
"1.20000","0.14103","-0.00042","-0.00042","0.48927"
"1.50000","0.16628","-0.00034","-0.00034","0.55888"
"1.80000","0.19141","-0.00028","-0.00028","0.62300"
"2.10000","0.21594","-0.00023","-0.00023","0.67931"
"2.40000","0.24053","-0.00017","-0.00017","0.73054"
"2.70000","0.26566","-0.00013","-0.00013","0.77927"
"3.00000","0.29094","-0.00008","-0.00008","0.82850"
"3.30000","0.31647","-0.00003","-0.00003","0.87941"
"3.60000","0.34127","0.00001","0.00001","0.92732"
"3.90000","0.36583","0.00006","0.00006","0.97133"
"4.20000","0.39060","0.00011","0.00011","1.01304"
"4.50000","0.41576","0.00015","0.00015","1.05396"
"4.80000","0.44134","0.00019","0.00019","1.09762"
"5.10000","0.46641","0.00023","0.00023","1.14144"
"5.40000","0.49112","0.00028","0.00028","1.18271"
"5.70000","0.51571","0.00032","0.00032","1.22175"
"6.00000","0.54051","0.00035","0.00035","1.26042"
"6.30000","0.56591","0.00040","0.00040","1.30087"
"6.60000","0.59132","0.00045","0.00045","1.34303"
"6.90000","0.61642","0.00049","0.00049","1.38455"
"7.20000","0.64098","0.00053","0.00053","1.42231"
"7.50000","0.66557","0.00058","0.00058","1.45843"
"7.80000","0.69070","0.00062","0.00062","1.49619"
"8.10000","0.71613","0.00067","0.00067","1.53586"
"8.40000","0.74150","0.00070","0.00070","1.57639"
"8.70000","0.76627","0.00075","0.00075","1.61548"
"9.00000","0.79080","0.00080","0.00080","1.65475"
"9.30000","0.81545","0.00085","0.00085","1.69212"
"9.60000","0.84077","0.00089","0.00089","1.73020"
"9.90000","0.86641","0.00094","0.00094","1.76851"
"10.20000","0.89139","0.00097","0.00097","1.80389"
"10.50000","0.91610","0.00099","0.00099","1.83857"
"10.80000","0.94057","0.00092","0.00092","1.86202"
"11.10000","0.96549","0.00093","0.00093","1.89312"
"11.40000","0.99116","0.00096","0.00096","1.92905"
"11.70000","1.01630","0.00099","0.00099","1.96659"
"12.00000","1.04143","0.00102","0.00102","2.00594"
"12.30000","1.06581","0.00095","0.00095","2.03444"
"12.60000","1.09055","0.00097","0.00097","2.06838"
"12.90000","1.11583","0.00100","0.00100","2.10206"
"13.20000","1.14120","0.00104","0.00104","2.13777"
"13.50000","1.16651","0.00108","0.00108","2.17628"
"13.80000","1.19110","0.00111","0.00111","2.21135"
"14.10000","1.21572","0.00113","0.00113","2.24268"
"14.40000","1.24055","0.00115","0.00115","2.26993"
"14.70000","1.26590","0.00118","0.00118","2.29947"
"15.00000","1.29133","0.00121","0.00121","2.33165"
"15.30000","1.31628","0.00125","0.00125","2.36432"
"15.60000","1.34105","0.00127","0.00127","2.39350"
"15.90000","1.36564","0.00128","0.00128","2.41412"
"16.20000","1.39074","0.00130","0.00130","2.43529"
"16.50000","1.41614","0.00132","0.00132","2.45827"
"16.80000","1.44139","0.00134","0.00134","2.48300"
"17.10000","1.46635","0.00137","0.00137","2.50788"
"17.40000","1.49081","0.00139","0.00139","2.52733"
"17.70000","1.51558","0.00141","0.00141","2.54490"
"18.00000","1.54078","0.00143","0.00143","2.56124"
"18.30000","1.56618","0.00145","0.00145","2.58052"
"18.60000","1.59149","0.00146","0.00146","2.60085"
"18.90000","1.61611","0.00148","0.00148","2.61501"
"19.20000","1.64070","0.00150","0.00150","2.62271"
"19.50000","1.66550","0.00150","0.00150","2.61797"
"19.80000","1.69093","0.00151","0.00151","2.60501"
"20.10000","1.71646","0.00151","0.00151","2.59516"
"33.14700","1.73424","0.00154","-0.00896","1.89162"
"33.44700","1.75654","0.00181","-0.00845","2.02091"
"33.74700","1.78173","0.00212","-0.00890","2.14366"
"34.04700","1.80713","0.00243","-0.00909","2.25783"
"34.34700","1.83250","0.00274","-0.00874","2.36482"
"34.64700","1.85712","0.00304","-0.00883","2.45705"
"34.94700","1.88174","0.00334","-0.00911","2.54005"
"35.24700","1.90648","0.00365","-0.00883","2.61426"
"35.54700","1.93197","0.00396","-0.00879","2.68525"
"35.84700","1.95744","0.00427","-0.00899","2.75194"
"36.14700","1.98233","0.00457","-0.00887","2.81086"
"36.44700","2.00704","0.00487","-0.00886","2.86412"
"36.74700","2.03151","0.00517","-0.00891","2.90732"
"37.04700","2.05667","0.00548","-0.00886","2.93942"
"37.34700","2.08219","0.00579","-0.00887","2.97553"
"37.64700","2.10741","0.00610","-0.00887","3.01246"
"37.94700","2.13230","0.00640","-0.00896","3.04236"
"38.24700","2.15668","0.00670","-0.00854","3.06204"
"38.54700","2.18151","0.00701","-0.00866","3.06816"
"38.84700","2.20683","0.00732","-0.00838","3.07319"
"39.14700","2.23226","0.00763","-0.00830","3.07695"
"39.44700","2.25745","0.00793","-0.00834","3.09309"
"39.74700","2.28207","0.00823","-0.00830","3.05223"
"40.04700","2.30672","0.00854","-0.00827","2.97665"
"40.34700","2.33161","0.00884","-0.00831","2.83777"
"40.64700","2.35710","0.00915","-0.00830","2.62677"
"40.94700","2.38251","0.00946","-0.00823","2.48803"
"41.24700","2.40734","0.00976","-0.00825","2.43650"
"41.54700","2.43187","0.01006","-0.00833","2.39632"
"41.84700","2.45652","0.01037","-0.00827","2.39847"
"42.14700","2.48171","0.01067","-0.00825","2.42632"
"42.44700","2.50720","0.01098","-0.00832","2.46732"
"42.74700","2.53236","0.01129","-0.00827","2.51449"
"43.04700","2.55731","0.01160","-0.00829","2.56308"
"43.34700","2.58166","0.01189","-0.00828","2.60119"
"43.64700","2.60661","0.01220","-0.00828","2.63759"
"43.94700","2.63193","0.01251","-0.00828","2.67411"
"44.24700","2.65733","0.01282","-0.00827","2.71456"
"44.54700","2.68243","0.01313","-0.00832","2.75404"
"44.84700","2.70699","0.01343","-0.00825","2.78243"
"45.14700","2.73173","0.01373","-0.00828","2.81241"
"45.44700","2.75650","0.01403","-0.00829","2.83401"
"45.74700","2.78208","0.01434","-0.00825","2.86337"
"46.04700","2.80739","0.01465","-0.00832","2.89653"
"46.34700","2.83229","0.01496","-0.00825","2.92529"
"46.64700","2.85687","0.01526","-0.00829","2.95689"
"46.94700","2.88143","0.01556","-0.00828","2.99007"
"47.24700","2.90681","0.01587","-0.00826","3.02715"
"47.54700","2.93215","0.01618","-0.00830","3.06713"
"47.84700","2.95743","0.01649","-0.00828","3.10756"
"48.14700","2.98220","0.01679","-0.00830","3.14586"
"48.44700","3.00667","0.01709","-0.00827","3.18107"
"48.74700","3.03165","0.01739","-0.00826","3.21510"
"49.04700","3.05690","0.01770","-0.00828","3.25056"
"49.34700","3.08240","0.01801","-0.00825","3.29019"
"49.64700","3.10741","0.01832","-0.00829","3.32750"
"49.94700","3.13194","0.01862","-0.00826","3.36120"
"50.24700","3.15656","0.01892","-0.00825","3.39216"
"50.54700","3.18154","0.01922","-0.00827","3.41849"
"50.84700","3.20712","0.01954","-0.00824","3.45158"
"51.14700","3.23243","0.01985","-0.00830","3.48925"
"51.44700","3.25723","0.02015","-0.00826","3.52284"
"51.74700","3.28185","0.02045","-0.00825","3.55089"
"52.04700","3.30650","0.02075","-0.00827","3.57126"
"52.34700","3.33194","0.02106","-0.00822","3.59538"
"52.64700","3.35737","0.02137","-0.00826","3.62509"
"52.94700","3.38244","0.02168","-0.00825","3.65577"
"53.24700","3.40712","0.02198","-0.00829","3.68388"
"53.54700","3.43162","0.02228","-0.00826","3.70749"
"53.84700","3.45660","0.02258","-0.00823","3.73313"
"54.14700","3.48197","0.02289","-0.00828","3.75923"
"54.44700","3.50741","0.02320","-0.00822","3.78969"
"54.74700","3.53239","0.02351","-0.00826","3.82266"
"55.04700","3.55685","0.02381","-0.00826","3.84897"
"55.26200","3.57533","0.02403","-0.00823","3.72504"
"55.29500","3.57825","0.02407","-0.00827","3.33751"
"55.55900","3.60013","0.02434","-0.00832","3.10530"
"55.85900","3.62487","0.02464","-0.00827","3.06700"
"56.15900","3.64940","0.02494","-0.00820","3.04793"
"56.45900","3.67417","0.02524","-0.00823","3.03548"
"56.75900","3.69957","0.02555","-0.00826","3.01669"
"57.05900","3.72494","0.02586","-0.00821","3.00892"
"57.35900","3.75010","0.02617","-0.00822","3.00450"
"57.65900","3.77469","0.02647","-0.00831","2.98965"
"57.95900","3.79931","0.02677","-0.00823","2.95711"
"58.25900","3.82432","0.02708","-0.00821","2.93986"
"58.55900","3.84973","0.02739","-0.00826","2.93120"
"58.85900","3.87516","0.02770","-0.00825","2.93267"
"59.15900","3.89993","0.02800","-0.00825","2.93612"
"59.45900","3.92455","0.02830","-0.00820","2.93826"
"59.75900","3.94920","0.02860","-0.00828","2.93618"
"60.05900","3.97442","0.02891","-0.00825","2.93508"
"60.35900","3.99997","0.02922","-0.00821","2.94470"
"60.65900","4.02505","0.02953","-0.00826","2.95666"
"60.95900","4.04979","0.02983","-0.00823","2.97116"
"61.25900","4.07425","0.03013","-0.00826","2.98286"
"61.55900","4.09914","0.03043","-0.00822","2.99470"
"61.85900","4.12479","0.03075","-0.00823","3.01106"
"62.15900","4.14989","0.03105","-0.00826","3.03089"
"62.45900","4.17508","0.03136","-0.00824","3.05401"
"62.75900","4.19958","0.03166","-0.00826","3.07281"
"63.05900","4.22423","0.03196","-0.00821","3.08829"
"63.35900","4.24948","0.03227","-0.00823","3.10075"
"63.65900","4.27480","0.03258","-0.00825","3.10907"
"63.95900","4.30017","0.03289","-0.00823","3.11690"
"64.25900","4.32485","0.03319","-0.00827","3.11439"
"64.55900","4.34941","0.03349","-0.00822","3.10212"
"64.85900","4.37424","0.03380","-0.00825","3.08346"
"65.15900","4.39946","0.03410","-0.00822","3.05380"
"65.45900","4.42498","0.03442","-0.00822","3.02552"
"65.75900","4.44999","0.03472","-0.00828","2.99328"
"66.05900","4.47482","0.03502","-0.00821","2.95876"
"66.35900","4.49935","0.03532","-0.00824","2.91560"
"66.65900","4.52436","0.03563","-0.00823","2.86623"
"66.95900","4.54974","0.03594","-0.00821","2.80745"
"67.25900","4.57505","0.03625","-0.00826","2.73538"
"67.55900","4.60009","0.03655","-0.00825","2.65024"
"67.85900","4.62456","0.03685","-0.00824","2.55305"
"68.15900","4.64930","0.03716","-0.00814","2.44671"
"68.45900","4.67437","0.03746","-0.00822","2.32040"
"68.75900","4.69983","0.03777","-0.00830","2.18707"
"69.05900","4.72515","0.03808","-0.00822","2.05548"
"69.35900","4.74983","0.03838","-0.00824","1.93367"
"69.65900","4.77445","0.03868","-0.00827","1.87361"
"69.95900","4.79916","0.03899","-0.00826","1.89224"
"70.25900","4.82456","0.03930","-0.00821","1.94856"
"70.55900","4.85005","0.03961","-0.00824","2.01899"
"70.85900","4.87503","0.03991","-0.00827","2.09004"
"71.15900","4.89977","0.04022","-0.00822","2.16039"
"71.45900","4.92421","0.04051","-0.00824","2.22518"
"71.75900","4.94922","0.04082","-0.00822","2.28816"
"72.05900","4.97484","0.04113","-0.00825","2.35108"
"72.35900","5.00006","0.04144","-0.00826","2.41270"
"72.65900","5.02495","0.04175","-0.00822","2.47018"
"72.95900","5.04939","0.04204","-0.00825","2.52022"
"73.25900","5.07419","0.04235","-0.00821","2.56602"
"73.55900","5.09947","0.04266","-0.00822","2.60934"
"73.85900","5.12487","0.04297","-0.00826","2.65090"
"74.15900","5.15015","0.04328","-0.00822","2.69231"
"74.45900","5.17474","0.04358","-0.00825","2.73016"
"74.75900","5.19942","0.04388","-0.00820","2.76415"
"75.05900","5.22422","0.04418","-0.00825","2.79607"
"75.35900","5.24972","0.04449","-0.00823","2.83077"
"75.65900","5.27512","0.04480","-0.00822","2.86865"
"75.95900","5.30001","0.04511","-0.00828","2.90538"
"76.25900","5.32463","0.04541","-0.00819","2.93988"
"76.55900","5.34919","0.04571","-0.00823","2.96960"
"76.85900","5.37435","0.04601","-0.00823","2.99987"
"77.15900","5.39981","0.04633","-0.00821","3.03203"
"77.45900","5.42504","0.04663","-0.00825","3.06820"
"77.75900","5.44999","0.04694","-0.00821","3.10366"
"78.05900","5.47440","0.04724","-0.00825","3.13460"
"78.35900","5.49929","0.04754","-0.00822","3.16484"
"78.65900","5.52451","0.04785","-0.00823","3.19376"
"78.95900","5.55000","0.04816","-0.00824","3.22664"
"79.25900","5.57513","0.04847","-0.00821","3.25928"
"79.55900","5.59969","0.04877","-0.00827","3.28989"
"79.85900","5.62440","0.04907","-0.00820","3.31913"
"80.15900","5.64917","0.04937","-0.00823","3.34543"
"80.45900","5.67473","0.04968","-0.00824","3.37521"
"80.75900","5.70004","0.04999","-0.00823","3.40776"
"81.05900","5.72499","0.05030","-0.00825","3.43766"
"81.35900","5.74955","0.05060","-0.00821","3.46436"
"81.65900","5.77414","0.05090","-0.00825","3.48817"
"81.95900","5.79942","0.05121","-0.00822","3.51387"
"82.25900","5.82482","0.05152","-0.00820","3.54327"
"82.55900","5.85007","0.05183","-0.00827","3.57538"
"82.85900","5.87491","0.05213","-0.00821","3.60693"
"83.15900","5.89937","0.05243","-0.00825","3.63448"
"83.45900","5.92429","0.05273","-0.00821","3.66210"
"83.75900","5.94955","0.05304","-0.00822","3.68937"
"84.05900","5.97501","0.05335","-0.00825","3.72100"
"84.35900","6.00014","0.05366","-0.00821","3.75265"
"84.65900","6.02464","0.05396","-0.00824","3.78072"
"84.95900","6.04926","0.05426","-0.00822","3.80666"
"85.25900","6.07418","0.05456","-0.00821","3.83270"
"85.55900","6.09973","0.05488","-0.00823","3.86175"
"85.85900","6.12511","0.05519","-0.00821","3.89370"
"86.15900","6.14994","0.05549","-0.00824","3.92286"
"86.45900","6.17462","0.05579","-0.00820","3.94755"
"86.75900","6.19912","0.05609","-0.00824","3.96840"
"87.05900","6.22458","0.05640","-0.00822","3.99296"
"87.35900","6.24995","0.05671","-0.00819","4.01995"
"87.65900","6.27511","0.05702","-0.00825","4.04887"
"87.95900","6.29982","0.05732","-0.00821","4.07560"
"88.25900","6.32429","0.05762","-0.00824","4.09865"
"88.55900","6.34927","0.05793","-0.00821","4.12006"
"88.85900","6.37459","0.05823","-0.00821","4.14141"
"89.15900","6.40005","0.05855","-0.00825","4.16934"
"89.45900","6.42503","0.05885","-0.00822","4.19799"
"89.75900","6.44956","0.05915","-0.00824","4.22335"
"90.05900","6.47433","0.05945","-0.00823","4.24564"
"90.35900","6.49922","0.05976","-0.00823","4.26518"
"90.65900","6.52492","0.06007","-0.00824","4.29106"
"90.95900","6.55002","0.06038","-0.00820","4.31691"
"91.25900","6.57498","0.06068","-0.00826","4.34136"
"91.55900","6.59944","0.06098","-0.00822","4.35947"
"91.85900","6.62415","0.06128","-0.00823","4.37673"
"92.15900","6.64965","0.06160","-0.00822","4.39622"
"92.45900","6.67487","0.06190","-0.00821","4.41869"
"92.75900","6.70006","0.06221","-0.00826","4.44632"
"93.05900","6.72468","0.06251","-0.00819","4.46994"
"93.35900","6.74930","0.06281","-0.00822","4.48856"
"93.65900","6.77425","0.06312","-0.00825","4.50715"
"93.95900","6.79962","0.06343","-0.00820","4.51454"
"94.25900","6.82512","0.06374","-0.00825","4.53546"
"94.55900","6.84998","0.06404","-0.00823","4.55652"
"94.85900","6.87457","0.06434","-0.00826","4.57737"
"95.15900","6.89928","0.06464","-0.00822","4.59511"
"95.45900","6.92441","0.06495","-0.00822","4.61292"
"95.75900","6.94996","0.06526","-0.00825","4.63344"
"96.05900","6.97512","0.06557","-0.00822","4.65414"
"96.35900","6.99983","0.06587","-0.00826","4.67331"
"96.65900","7.02445","0.06617","-0.00821","4.68871"
"96.95900","7.04916","0.06648","-0.00823","4.70374"
"97.25900","7.07460","0.06679","-0.00826","4.71952"
"97.55900","7.09997","0.06710","-0.00820","4.74175"
"97.85900","7.12510","0.06740","-0.00826","4.76598"
"98.15900","7.14972","0.06770","-0.00823","4.78506"
"98.45900","7.17428","0.06800","-0.00823","4.80037"
"98.75900","7.19941","0.06831","-0.00822","4.81661"
"99.05900","7.22466","0.06862","-0.00822","4.83409"
"99.35900","7.25013","0.06893","-0.00827","4.85714"
"99.65900","7.27493","0.06923","-0.00820","4.87811"
"99.95900","7.29955","0.06954","-0.00824","4.89685"
"100.25900","7.32425","0.06984","-0.00824","4.91143"
"100.55900","7.34942","0.07014","-0.00821","4.92477"
"100.85900","7.37500","0.07046","-0.00823","4.94215"
"101.15900","7.40001","0.07076","-0.00822","4.95591"
"101.45900","7.42478","0.07107","-0.00825","4.96919"
"101.75900","7.44922","0.07136","-0.00821","4.97769"
"102.05900","7.47414","0.07167","-0.00821","4.96372"
"102.35900","7.49978","0.07198","-0.00823","4.97677"
"102.65900","7.52495","0.07229","-0.00820","4.98936"
"102.95900","7.55008","0.07260","-0.00824","5.00390"
"103.25900","7.57452","0.07289","-0.00820","4.95203"
"103.55900","7.59929","0.07320","-0.00823","4.94696"
"103.85900","7.62439","0.07350","-0.00822","4.91977"
"104.15900","7.64982","0.07381","-0.00820","4.92111"
"104.45900","7.67516","0.07412","-0.00825","4.92211"
"104.75900","7.69981","0.07443","-0.00820","4.92576"
"105.05900","7.72440","0.07473","-0.00824","4.92548"
"105.35900","7.74923","0.07503","-0.00822","4.92128"
"105.65900","7.77449","0.07534","-0.00820","4.91444"
"105.95900","7.79995","0.07565","-0.00823","4.88708"
"106.25900","7.82502","0.07596","-0.00820","4.81725"
"106.55900","7.84979","0.07626","-0.00823","4.77725"
"106.85900","7.87438","0.07656","-0.00821","4.74486"
"107.15900","7.89936","0.07686","-0.00821","4.70713"
"107.45900","7.92479","0.07717","-0.00820","4.67748"
"107.75900","7.95005","0.07748","-0.00826","4.65408"
"108.05900","7.97506","0.07779","-0.00828","4.63227"
"108.35900","7.99956","0.07809","-0.00820","4.60373"
"108.65900","8.02427","0.07839","-0.00819","4.57395"
"108.95900","8.04940","0.07870","-0.00824","4.54303"
"109.25900","8.07480","0.07901","-0.00819","4.48422"
"109.55900","8.10017","0.07932","-0.00824","4.44588"
"109.85900","8.12485","0.07962","-0.00822","4.41603"
"110.15900","8.14944","0.07992","-0.00822","4.38979"
"110.45900","8.17418","0.08022","-0.00821","4.36246"
"110.75900","8.19959","0.08053","-0.00821","4.34046"
"111.05900","8.22511","0.08084","-0.00824","4.32382"
"111.35900","8.25000","0.08115","-0.00819","4.30666"
"111.65900","8.27477","0.08145","-0.00825","4.27970"
"111.95900","8.29918","0.08175","-0.00821","4.24754"
"112.25900","8.32422","0.08205","-0.00819","4.21130"
"112.55900","8.34989","0.08237","-0.00824","4.18232"
"112.85900","8.37505","0.08268","-0.00820","4.15509"
"113.15900","8.39998","0.08298","-0.00823","4.10734"
"113.45900","8.42435","0.08328","-0.00820","4.05359"
"113.75900","8.44921","0.08358","-0.00820","3.99440"
"114.05900","8.47441","0.08389","-0.00822","3.93893"
"114.35900","8.49987","0.08420","-0.00819","3.89841"
"114.65900","8.52515","0.08451","-0.00823","3.87206"
"114.95900","8.54977","0.08481","-0.00821","3.85217"
"115.25900","8.57445","0.08511","-0.00820","3.83253"
"115.55900","8.59919","0.08541","-0.00823","3.79882"
"115.85900","8.62480","0.08573","-0.00817","3.77248"
"116.15900","8.65009","0.08604","-0.00823","3.75487"
"116.45900","8.67504","0.08634","-0.00821","3.73789"
"116.75900","8.69957","0.08664","-0.00822","3.71984"
"117.05900","8.72422","0.08694","-0.00821","3.69757"
"117.35900","8.74935","0.08725","-0.00820","3.67538"
"117.65900","8.77481","0.08756","-0.00824","3.65765"
"117.95900","8.80006","0.08787","-0.00823","3.64690"
"118.25900","8.82498","0.08817","-0.00824","3.63744"
"118.55900","8.84933","0.08847","-0.00822","3.62174"
"118.85900","8.87428","0.08877","-0.00819","3.60472"
"119.15900","8.89963","0.08908","-0.00823","3.58943"
"119.45900","8.92500","0.08939","-0.00821","3.57865"
"119.75900","8.95013","0.08970","-0.00822","3.56923"
"120.05900","8.97475","0.09000","-0.00821","3.55567"
"120.35900","8.99937","0.09030","-0.00818","3.54019"
"120.65900","9.02423","0.09061","-0.00822","3.52396"
"120.95900","9.04972","0.09092","-0.00818","3.51318"
"121.25900","9.07510","0.09123","-0.00822","3.50748"
"121.55900","9.09996","0.09153","-0.00822","3.50066"
"121.85900","9.12458","0.09183","-0.00820","3.49281"
"122.15900","9.14913","0.09213","-0.00822","3.48097"
"122.45900","9.17442","0.09244","-0.00819","3.47445"
"122.75900","9.19985","0.09275","-0.00823","3.47193"
"123.05900","9.22510","0.09306","-0.00819","3.47120"
"123.35900","9.24996","0.09336","-0.00822","3.46964"
"123.65900","9.27428","0.09366","-0.00823","3.46054"
"123.95900","9.29932","0.09397","-0.00817","3.45371"
"124.25900","9.32451","0.09428","-0.00821","3.44631"
"124.55900","9.35004","0.09459","-0.00822","3.44502"
"124.85900","9.37511","0.09489","-0.00823","3.44330"
"125.15900","9.39967","0.09519","-0.00819","3.43899"
"125.45900","9.42429","0.09549","-0.00820","3.43026"
"125.75900","9.44915","0.09580","-0.00825","3.41197"
"126.05900","9.47476","0.09611","-0.00818","3.40362"
"126.35900","9.50007","0.09642","-0.00820","3.39895"
"126.65900","9.52496","0.09672","-0.00822","3.39371"
"126.95900","9.54958","0.09702","-0.00820","3.38406"
"127.25900","9.57414","0.09732","-0.00822","3.37293"
"127.55900","9.59958","0.09764","-0.00819","3.36490"
"127.85900","9.62495","0.09795","-0.00823","3.35952"
"128.15900","9.65017","0.09825","-0.00820","3.35738"
"128.45900","9.67482","0.09856","-0.00819","3.35333"
"128.75900","9.69932","0.09885","-0.00823","3.34690"
"129.05900","9.72424","0.09916","-0.00818","3.33910"
"129.35900","9.74961","0.09947","-0.00819","3.33199"
"129.65900","9.77505","0.09978","-0.00820","3.33204"
"129.95900","9.80006","0.10009","-0.00823","3.33188"
"130.25900","9.82459","0.10038","-0.00820","3.32875"
"130.55900","9.84927","0.10069","-0.00817","3.32247"
"130.85900","9.87425","0.10099","-0.00822","3.31728"
"131.15900","9.89989","0.10130","-0.00820","3.31750"
"131.45900","9.92508","0.10161","-0.00818","3.31989"
"131.75900","9.94994","0.10192","-0.00822","3.32005"
"132.05900","9.97447","0.10222","-0.00816","3.31752"
"132.35900","9.99915","0.10252","-0.00820","3.31116"
"132.65900","10.02465","0.10283","-0.00819","3.30886"
"132.95900","10.04990","0.10314","-0.00819","3.30951"
"133.25900","10.07509","0.10345","-0.00820","3.31304"
"133.55900","10.09971","0.10375","-0.00815","3.31272"
"133.85900","10.12421","0.10405","-0.00822","3.30913"
"134.15900","10.14928","0.10435","-0.00819","3.30469"
"134.45900","10.17459","0.10466","-0.00817","3.30228"
"134.75900","10.20008","0.10497","-0.00820","3.30320"
"135.05900","10.22497","0.10528","-0.00820","3.30291"
"135.35900","10.24953","0.10558","-0.00821","3.29939"
"135.65900","10.27433","0.10588","-0.00817","3.29350"
"135.95900","10.29938","0.10619","-0.00822","3.28754"
"136.25900","10.32499","0.10650","-0.00818","3.28935"
"136.55900","10.35009","0.10681","-0.00818","3.29307"
"136.85900","10.37486","0.10711","-0.00820","3.29587"
"137.15900","10.39942","0.10741","-0.00818","3.29131"
"137.45900","10.42416","0.10771","-0.00821","3.28572"
"137.75900","10.44959","0.10802","-0.00816","3.28477"
"138.05900","10.47491","0.10833","-0.00818","3.28580"
"138.35900","10.50013","0.10864","-0.00821","3.29051"
"138.65900","10.52469","0.10894","-0.00817","3.29089"
"138.95900","10.54931","0.10924","-0.00820","3.28927"
"139.25900","10.57429","0.10954","-0.00818","3.28698"
"139.55900","10.59969","0.10985","-0.00820","3.28499"
"139.85900","10.62518","0.11017","-0.00821","3.28727"
"140.15900","10.64995","0.11047","-0.00818","3.28651"
"140.45900","10.67457","0.11077","-0.00821","3.28305"
"140.75900","10.69919","0.11107","-0.00816","3.27529"
"141.05900","10.72444","0.11138","-0.00820","3.26662"
"141.35900","10.75000","0.11169","-0.00820","3.26048"
"141.65900","10.77504","0.11200","-0.00819","3.25252"
"141.95900","10.79975","0.11230","-0.00820","3.23341"
"142.25900","10.82422","0.11260","-0.00819","3.21472"
"142.55900","10.84920","0.11290","-0.00820","3.19882"
"142.85900","10.87475","0.11322","-0.00816","3.18761"
"143.15900","10.89994","0.11352","-0.00819","3.17926"
"143.45900","10.92508","0.11383","-0.00822","3.17339"
"143.75900","10.94954","0.11413","-0.00816","3.16478"
"144.05900","10.97423","0.11443","-0.00820","3.15360"
"144.35900","10.99951","0.11474","-0.00819","3.14231"
"144.65900","11.02482","0.11505","-0.00819","3.13287"
"144.95900","11.05013","0.11536","-0.00819","3.12838"
"145.25900","11.07484","0.11566","-0.00817","3.12171"
"145.55900","11.09940","0.11596","-0.00823","3.11396"
"145.85900","11.12426","0.11626","-0.00818","3.10392"
"146.15900","11.14942","0.11657","-0.00818","3.09306"
"146.45900","11.17498","0.11688","-0.00820","3.08789"
"146.75900","11.19999","0.11719","-0.00818","3.08439"
"147.05900","11.22479","0.11749","-0.00821","3.08031"
"147.35900","11.24935","0.11779","-0.00816","3.07164"
"147.65900","11.27433","0.11810","-0.00819","3.06221"
"147.95900","11.29982","0.11841","-0.00820","3.05670"
"148.25900","11.32501","0.11872","-0.00818","3.05242"
"148.55900","11.35008","0.11902","-0.00821","3.04992"
"148.85900","11.37449","0.11932","-0.00817","3.04282"
"149.15900","11.39929","0.11962","-0.00819","3.03650"
"149.45900","11.42436","0.11993","-0.00819","3.02799"
"149.75900","11.44980","0.12024","-0.00816","3.02345"
"150.05900","11.47514","0.12055","-0.00822","3.02113"
"150.35900","11.49982","0.12085","-0.00817","3.01728"
"150.65900","11.52447","0.12115","-0.00818","3.01238"
"150.95900","11.54915","0.12145","-0.00818","3.00168"
"151.25900","11.57464","0.12177","-0.00816","2.99608"
"151.55900","11.60008","0.12208","-0.00821","2.99429"
"151.85900","11.62503","0.12238","-0.00815","2.99051"
"152.15900","11.64977","0.12268","-0.00818","2.98385"
"152.45900","11.67417","0.12298","-0.00820","2.97071"
"152.75900","11.69931","0.12329","-0.00817","2.95680"
"153.05900","11.72483","0.12360","-0.00819","2.93852"
"153.35900","11.75008","0.12391","-0.00818","2.92422"
"153.65900","11.77497","0.12421","-0.00819","2.91124"
"153.95900","11.79938","0.12451","-0.00817","2.89623"
"154.25900","11.82415","0.12481","-0.00815","2.87439"
"154.55900","11.84946","0.12512","-0.00820","2.85434"
"154.85900","11.87487","0.12543","-0.00814","2.84115"
"155.15900","11.90015","0.12574","-0.00819","2.83175"
"155.45900","11.92477","0.12604","-0.00818","2.81947"
"155.75900","11.94948","0.12635","-0.00817","2.80431"
"156.05900","11.97422","0.12665","-0.00820","2.78501"
"156.35900","11.99971","0.12696","-0.00815","2.77129"
"156.65900","12.02514","0.12727","-0.00820","2.76168"
"156.95900","12.05003","0.12757","-0.00819","2.75124"
"157.25900","12.07456","0.12787","-0.00817","2.74163"
"157.55900","12.09918","0.12817","-0.00819","2.72800"
"157.85900","12.12434","0.12848","-0.00815","2.71495"
"158.15900","12.14984","0.12879","-0.00820","2.70285"
"158.45900","12.17503","0.12910","-0.00818","2.68946"
"158.75900","12.19998","0.12941","-0.00817","2.66961"
"159.05900","12.22436","0.12970","-0.00821","2.64880"
"159.35900","12.24928","0.13001","-0.00816","2.63016"
"159.65900","12.27456","0.13032","-0.00820","2.61091"
"159.95900","12.29996","0.13063","-0.00819","2.57509"
"160.25900","12.32513","0.13094","-0.00819","2.55600"
"160.55900","12.34972","0.13124","-0.00817","2.53875"
"160.85900","12.37442","0.13154","-0.00814","2.52191"
"161.15900","12.39917","0.13184","-0.00819","2.50242"
"161.45900","12.42472","0.13215","-0.00815","2.48869"
"161.75900","12.45006","0.13246","-0.00816","2.47435"
"162.05900","12.47498","0.13277","-0.00819","2.45823"
"162.35900","12.49957","0.13307","-0.00814","2.43835"
"162.65900","12.52413","0.13337","-0.00817","2.40869"
"162.95900","12.54941","0.13368","-0.00814","2.38071"
"163.25900","12.57482","0.13399","-0.00817","2.35988"
"163.55900","12.60010","0.13429","-0.00821","2.33582"
"163.85900","12.62493","0.13460","-0.00816","2.31788"
"164.15900","12.64937","0.13490","-0.00819","2.30051"
"164.45900","12.67432","0.13520","-0.00817","2.28416"
"164.75900","12.69951","0.13551","-0.00818","2.26914"
"165.05900","12.72503","0.13582","-0.00818","2.25889"
"165.35900","12.75011","0.13613","-0.00814","2.24738"
"165.65900","12.77466","0.13643","-0.00821","2.23384"
"165.95900","12.79925","0.13673","-0.00816","2.21882"
"166.25900","12.82417","0.13703","-0.00814","2.20446"
"166.55900","12.84973","0.13734","-0.00820","2.19359"
"166.85900","12.87510","0.13765","-0.00817","2.18711"
"167.15900","12.89996","0.13796","-0.00816","2.18018"
"167.45900","12.92458","0.13826","-0.00812","2.17119"
"167.75900","12.94920","0.13856","-0.00820","2.16018"
"168.05900","12.97457","0.13887","-0.00819","2.15242"
"168.35900","13.00001","0.13918","-0.00815","2.14618"
"168.65900","13.02511","0.13949","-0.00816","2.14079"
"168.95900","13.04985","0.13979","-0.00816","2.13194"
"169.25900","13.07432","0.14009","-0.00819","2.11984"
"169.55900","13.09927","0.14039","-0.00817","2.10733"
"169.85900","13.12461","0.14070","-0.00813","2.08367"
"170.15900","13.15004","0.14101","-0.00821","2.07106"
"170.45900","13.17508","0.14132","-0.00816","2.05950"
"170.75900","13.19958","0.14162","-0.00817","2.04629"
"171.05900","13.22432","0.14192","-0.00818","2.03278"
"171.35900","13.24915","0.14222","-0.00814","2.01910"
"171.65900","13.27492","0.14254","-0.00818","2.01081"
"171.95900","13.30005","0.14285","-0.00816","2.00270"
"172.25900","13.32494","0.14315","-0.00818","1.99549"
"172.55900","13.34947","0.14345","-0.00817","1.98477"
"172.85900","13.37415","0.14375","-0.00813","1.97088"
"173.15900","13.39970","0.14406","-0.00818","1.96080"
"173.45900","13.42486","0.14437","-0.00816","1.95183"
"173.75900","13.45006","0.14468","-0.00818","1.94569"
"174.05900","13.47471","0.14498","-0.00819","1.93679"
"174.35900","13.49926","0.14528","-0.00811","1.92605"
"174.65900","13.52427","0.14559","-0.00817","1.91472"
"174.95900","13.54962","0.14590","-0.00815","1.90483"
"175.25900","13.57511","0.14621","-0.00814","1.89706"
"175.55900","13.59997","0.14651","-0.00818","1.88955"
"175.85900","13.62456","0.14681","-0.00816","1.88014"
"176.15900","13.64930","0.14711","-0.00818","1.86220"
"176.45900","13.67425","0.14742","-0.00814","1.84812"
"176.75900","13.69993","0.14773","-0.00818","1.83883"
"177.05900","13.72512","0.14804","-0.00819","1.83081"
"177.35900","13.74989","0.14834","-0.00814","1.82001"
"177.65900","13.77445","0.14864","-0.00817","1.80209"
"177.95900","13.79919","0.14894","-0.00814","1.78086"
"178.25900","13.82456","0.14925","-0.00817","1.76129"
"178.55900","13.84996","0.14956","-0.00816","1.74697"
"178.85900","13.87512","0.14987","-0.00816","1.73504"
"179.15900","13.89974","0.15017","-0.00819","1.72164"
"179.45900","13.92430","0.15047","-0.00812","1.70634"
"179.75900","13.94931","0.15078","-0.00814","1.69115"
"180.05900","13.97469","0.15109","-0.00817","1.67560"
"180.35900","14.00021","0.15140","-0.00816","1.66538"
"180.65900","14.02498","0.15170","-0.00817","1.65511"
"180.95900","14.04951","0.15200","-0.00812","1.64373"
"181.25900","14.07425","0.15230","-0.00816","1.63044"
"181.55900","14.09941","0.15261","-0.00815","1.61706"
"181.85900","14.12500","0.15292","-0.00813","1.60818"
"182.15900","14.15004","0.15323","-0.00820","1.59821"
"182.45900","14.17478","0.15353","-0.00816","1.58770"
"182.75900","14.19928","0.15383","-0.00817","1.57557"
"183.05900","14.22414","0.15414","-0.00815","1.56268"
"183.35900","14.24978","0.15445","-0.00815","1.55415"
"183.65900","14.27491","0.15476","-0.00820","1.54789"
"183.95900","14.30007","0.15506","-0.00814","1.54372"
"184.25900","14.32454","0.15536","-0.00815","1.53496"
"184.55900","14.34925","0.15566","-0.00815","1.52447"
"184.85900","14.37444","0.15597","-0.00812","1.51549"
"185.15900","14.39982","0.15628","-0.00817","1.50811"
"185.45900","14.42519","0.15659","-0.00816","1.50514"
"185.75900","14.44981","0.15689","-0.00817","1.50057"
"186.05900","14.47443","0.15719","-0.00813","1.49428"
"186.35900","14.49920","0.15750","-0.00815","1.48680"
"186.65900","14.52448","0.15781","-0.00820","1.48069"
"186.95900","14.54994","0.15812","-0.00811","1.47774"
"187.25900","14.57498","0.15842","-0.00816","1.47579"
"187.55900","14.59978","0.15873","-0.00817","1.47223"
"187.85900","14.62434","0.15903","-0.00814","1.46465"
"188.15900","14.64932","0.15933","-0.00816","1.45762"
"188.45900","14.67476","0.15964","-0.00813","1.45219"
"188.75900","14.70004","0.15995","-0.00817","1.44894"
"189.05900","14.72505","0.16026","-0.00815","1.44641"
"189.35900","14.74952","0.16055","-0.00813","1.44072"
"189.65900","14.77426","0.16086","-0.00817","1.43353"
"189.95900","14.79939","0.16116","-0.00809","1.42587"
"190.25900","14.82482","0.16148","-0.00815","1.42129"
"190.55900","14.85017","0.16178","-0.00818","1.41879"
"190.85900","14.87482","0.16209","-0.00813","1.41435"
"191.15900","14.89938","0.16239","-0.00816","1.40872"
"191.45900","14.92418","0.16269","-0.00814","1.40210"
"191.75900","14.94958","0.16300","-0.00817","1.39885"
"192.05900","14.97507","0.16331","-0.00814","1.39669"
"192.35900","15.00005","0.16362","-0.00814","1.39069"
"192.65900","15.02479","0.16392","-0.00818","1.38351"
"192.95900","15.04923","0.16422","-0.00810","1.37338"
"193.25900","15.07421","0.16452","-0.00813","1.35951"
"193.55900","15.09989","0.16484","-0.00816","1.35484"
"193.85900","15.12505","0.16514","-0.00815","1.35272"
"194.15900","15.15000","0.16545","-0.00814","1.35046"
"194.45900","15.17438","0.16575","-0.00811","1.33909"
"194.75900","15.19918","0.16605","-0.00816","1.32963"
"195.05900","15.22443","0.16636","-0.00813","1.32288"
"195.35900","15.24983","0.16667","-0.00813","1.31872"
"195.65900","15.27515","0.16698","-0.00816","1.31513"
"195.95900","15.29974","0.16728","-0.00811","1.30793"
"196.25900","15.32445","0.16758","-0.00815","1.29571"
"196.55900","15.34918","0.16788","-0.00814","1.28403"
"196.85900","15.37477","0.16819","-0.00813","1.27575"
"197.15900","15.40011","0.16850","-0.00816","1.26655"
"197.45900","15.42503","0.16881","-0.00813","1.23968"
"197.75900","15.44959","0.16911","-0.00816","1.22730"
"198.05900","15.47418","0.16941","-0.00813","1.21576"
"198.35900","15.49940","0.16972","-0.00814","1.20672"
"198.65900","15.52477","0.17003","-0.00816","1.19924"
"198.95900","15.55003","0.17034","-0.00811","1.19276"
"199.25900","15.57492","0.17064","-0.00816","1.18287"
"199.55900","15.59942","0.17094","-0.00815","1.16717"
"199.85900","15.62431","0.17124","-0.00811","1.15152"
"200.15900","15.64956","0.17155","-0.00815","1.13844"
"200.45900","15.67502","0.17186","-0.00813","1.13025"
"200.75900","15.70012","0.17217","-0.00816","1.11842"
"201.05900","15.72474","0.17247","-0.00810","1.10406"
"201.35900","15.74939","0.17277","-0.00805","1.09088"
"201.65900","15.77422","0.17307","-0.00820","1.07770"
"201.95900","15.79969","0.17339","-0.00825","1.06305"
"202.25900","15.82506","0.17370","-0.00818","1.05055"
"202.46600","15.84142","0.17390","-0.00811","1.04155"