File: Design_Project-Carbon_Fiber_Rim/Manufacturing/Material Testing/Day 1/number2.is_tens_RawData/Specimen_RawData_1.csv
Time,Extension,Tensile strain (Clip on Extensometer),Clip on Extensometer,Load
(s),(mm),(mm/mm),(mm/mm),(kN)
"0.00000","0.03435","-0.00554","-0.00554","0.10743"
"0.10000","0.04906","-0.00545","-0.00545","0.22025"
"0.20000","0.05364","-0.00543","-0.00543","0.22059"
"0.30000","0.06274","-0.00541","-0.00541","0.25695"
"0.40000","0.07051","-0.00538","-0.00538","0.28434"
"0.50000","0.07910","-0.00535","-0.00535","0.31646"
"0.60000","0.08811","-0.00532","-0.00532","0.34540"
"0.70000","0.09616","-0.00530","-0.00530","0.36919"
"0.80000","0.10381","-0.00527","-0.00527","0.39522"
"0.90000","0.11264","-0.00525","-0.00525","0.42363"
"1.00000","0.12135","-0.00522","-0.00522","0.44760"
"1.10000","0.12921","-0.00520","-0.00520","0.46911"
"1.20000","0.13735","-0.00517","-0.00517","0.49423"
"1.30000","0.14636","-0.00515","-0.00515","0.51811"
"1.40000","0.15474","-0.00513","-0.00513","0.53638"
"1.50000","0.16221","-0.00510","-0.00510","0.55565"
"1.60000","0.17071","-0.00508","-0.00508","0.58172"
"1.70000","0.17972","-0.00506","-0.00506","0.60445"
"1.80000","0.18785","-0.00504","-0.00504","0.62186"
"1.90000","0.19554","-0.00502","-0.00502","0.64179"
"2.00000","0.20437","-0.00500","-0.00500","0.66467"
"2.10000","0.21314","-0.00498","-0.00498","0.68236"
"2.20000","0.22082","-0.00496","-0.00496","0.69658"
"2.30000","0.22887","-0.00493","-0.00493","0.71729"
"2.40000","0.23794","-0.00491","-0.00491","0.73733"
"2.50000","0.24631","-0.00490","-0.00490","0.75018"
"2.60000","0.25388","-0.00488","-0.00488","0.76475"
"2.70000","0.26244","-0.00486","-0.00486","0.78453"
"2.80000","0.27151","-0.00485","-0.00485","0.80051"
"2.90000","0.27940","-0.00483","-0.00483","0.81185"
"3.00000","0.28715","-0.00481","-0.00481","0.82798"
"3.10000","0.29607","-0.00479","-0.00479","0.84630"
"3.20000","0.30471","-0.00478","-0.00478","0.85954"
"3.30000","0.31249","-0.00476","-0.00476","0.87204"
"3.40000","0.32075","-0.00475","-0.00475","0.88939"
"3.50000","0.32973","-0.00473","-0.00473","0.90482"
"3.60000","0.33789","-0.00472","-0.00472","0.91571"
"3.70000","0.34549","-0.00471","-0.00471","0.92765"
"3.80000","0.35410","-0.00469","-0.00469","0.94552"
"3.90000","0.36305","-0.00467","-0.00467","0.96016"
"4.00000","0.37104","-0.00466","-0.00466","0.97028"
"4.10000","0.37896","-0.00464","-0.00464","0.98470"
"4.20000","0.38785","-0.00463","-0.00463","1.00157"
"4.30000","0.39644","-0.00461","-0.00461","1.01372"
"4.40000","0.40407","-0.00460","-0.00460","1.02426"
"4.50000","0.41232","-0.00459","-0.00459","1.04034"
"4.60000","0.42130","-0.00457","-0.00457","1.05495"
"4.70000","0.42962","-0.00456","-0.00456","1.06474"
"4.80000","0.43724","-0.00455","-0.00455","1.07612"
"4.90000","0.44592","-0.00453","-0.00453","1.09238"
"5.00000","0.45484","-0.00452","-0.00452","1.10512"
"5.10000","0.46271","-0.00451","-0.00451","1.11327"
"5.20000","0.47045","-0.00450","-0.00450","1.12666"
"5.30000","0.47943","-0.00448","-0.00448","1.14245"
"5.40000","0.48808","-0.00447","-0.00447","1.15239"
"5.50000","0.49576","-0.00446","-0.00446","1.16213"
"5.60000","0.50402","-0.00444","-0.00444","1.17781"
"5.70000","0.51306","-0.00443","-0.00443","1.19116"
"5.80000","0.52114","-0.00442","-0.00442","1.19978"
"5.90000","0.52876","-0.00441","-0.00441","1.21200"
"6.00000","0.53759","-0.00439","-0.00439","1.22724"
"6.10000","0.54642","-0.00438","-0.00438","1.23828"
"6.20000","0.55431","-0.00437","-0.00437","1.24723"
"6.30000","0.56233","-0.00436","-0.00436","1.26145"
"6.40000","0.57128","-0.00434","-0.00434","1.27580"
"6.50000","0.57969","-0.00433","-0.00433","1.28438"
"6.60000","0.58734","-0.00432","-0.00432","1.29402"
"6.70000","0.59572","-0.00431","-0.00431","1.30876"
"6.80000","0.60467","-0.00430","-0.00430","1.32120"
"6.90000","0.61274","-0.00429","-0.00429","1.32926"
"7.00000","0.62064","-0.00428","-0.00428","1.34120"
"7.10000","0.62938","-0.00426","-0.00426","1.35592"
"7.20000","0.63815","-0.00425","-0.00425","1.36595"
"7.30000","0.64586","-0.00424","-0.00424","1.37329"
"7.40000","0.65388","-0.00423","-0.00423","1.38645"
"7.50000","0.66286","-0.00421","-0.00421","1.40030"
"7.60000","0.67141","-0.00421","-0.00421","1.40931"
"7.70000","0.67907","-0.00421","-0.00421","1.41752"
"7.80000","0.68744","-0.00419","-0.00419","1.43137"
"7.90000","0.69645","-0.00418","-0.00418","1.44320"
"8.00000","0.70447","-0.00417","-0.00417","1.44936"
"8.10000","0.71209","-0.00416","-0.00416","1.45966"
"8.20000","0.72104","-0.00415","-0.00415","1.47422"
"8.30000","0.72981","-0.00414","-0.00414","1.48306"
"8.40000","0.73756","-0.00413","-0.00413","1.48961"
"8.50000","0.74560","-0.00412","-0.00412","1.50147"
"8.60000","0.75464","-0.00411","-0.00411","1.51281"
"8.70000","0.76293","-0.00410","-0.00410","1.51793"
"8.80000","0.77052","-0.00410","-0.00410","1.52492"
"8.90000","0.77908","-0.00409","-0.00409","1.53706"
"9.00000","0.78806","-0.00408","-0.00408","1.54654"
"9.10000","0.79605","-0.00407","-0.00407","1.55184"
"9.20000","0.80391","-0.00406","-0.00406","1.56263"
"9.30000","0.81277","-0.00405","-0.00405","1.57521"
"9.40000","0.82139","-0.00404","-0.00404","1.58268"
"9.50000","0.82910","-0.00404","-0.00404","1.58931"
"9.60000","0.83727","-0.00402","-0.00402","1.60138"
"9.70000","0.84631","-0.00401","-0.00401","1.61251"
"9.80000","0.85463","-0.00401","-0.00401","1.61918"
"9.90000","0.86240","-0.00399","-0.00399","1.62792"
"10.00000","0.87090","-0.00399","-0.00399","1.64048"
"10.10000","0.87973","-0.00397","-0.00397","1.64963"
"10.20000","0.88765","-0.00397","-0.00397","1.65561"
"10.30000","0.89549","-0.00396","-0.00396","1.66648"
"10.40000","0.90441","-0.00394","-0.00394","1.67948"
"10.50000","0.91309","-0.00394","-0.00394","1.68808"
"10.60000","0.92089","-0.00393","-0.00393","1.69516"
"10.70000","0.92900","-0.00392","-0.00392","1.70660"
"10.80000","0.93804","-0.00390","-0.00390","1.71870"
"10.90000","0.94629","-0.00390","-0.00390","1.72576"
"11.00000","0.95380","-0.00388","-0.00388","1.73485"
"11.10000","0.96251","-0.00387","-0.00387","1.74878"
"11.20000","0.97146","-0.00385","-0.00385","1.75819"
"11.30000","0.97941","-0.00385","-0.00385","1.76476"
"11.40000","0.98725","-0.00384","-0.00384","1.77609"
"11.50000","0.99617","-0.00382","-0.00382","1.78922"
"11.60000","1.00463","-0.00382","-0.00382","1.79633"
"11.70000","1.01226","-0.00381","-0.00381","1.80332"
"11.80000","1.02064","-0.00379","-0.00379","1.81669"
"11.90000","1.02968","-0.00378","-0.00378","1.82761"
"12.00000","1.03790","-0.00377","-0.00377","1.83472"
"12.10000","1.04556","-0.00376","-0.00376","1.84435"
"12.20000","1.05429","-0.00375","-0.00375","1.85729"
"12.30000","1.06309","-0.00374","-0.00374","1.86579"
"12.40000","1.07093","-0.00373","-0.00373","1.87117"
"12.50000","1.07891","-0.00372","-0.00372","1.88296"
"12.60000","1.08786","-0.00371","-0.00371","1.89516"
"12.70000","1.09636","-0.00370","-0.00370","1.90231"
"12.80000","1.10411","-0.00369","-0.00369","1.91053"
"12.90000","1.11248","-0.00368","-0.00368","1.92264"
"13.00000","1.12140","-0.00367","-0.00367","1.93270"
"13.10000","1.12942","-0.00366","-0.00366","1.93799"
"13.20000","1.13713","-0.00366","-0.00366","1.94675"
"13.30000","1.14587","-0.00365","-0.00365","1.95901"
"13.40000","1.15473","-0.00364","-0.00364","1.96731"
"13.50000","1.16272","-0.00363","-0.00363","1.97302"
"13.60000","1.17064","-0.00362","-0.00362","1.98343"
"13.70000","1.17956","-0.00362","-0.00362","1.99495"
"13.80000","1.18803","-0.00361","-0.00361","2.00066"
"13.90000","1.19553","-0.00360","-0.00360","2.00727"
"14.00000","1.20406","-0.00358","-0.00358","2.02033"
"14.10000","1.21313","-0.00357","-0.00357","2.03021"
"14.20000","1.22124","-0.00357","-0.00357","2.03569"
"14.30000","1.22889","-0.00355","-0.00355","2.04505"
"14.40000","1.23766","-0.00354","-0.00354","2.05791"
"14.50000","1.24640","-0.00354","-0.00354","2.06548"
"14.60000","1.25414","-0.00353","-0.00353","2.07172"
"14.70000","1.26225","-0.00351","-0.00351","2.08410"
"14.80000","1.27129","-0.00350","-0.00350","2.09445"
"14.90000","1.27964","-0.00349","-0.00349","2.10078"
"15.00000","1.28726","-0.00348","-0.00348","2.10907"
"15.10000","1.29582","-0.00348","-0.00348","2.12182"
"15.20000","1.30474","-0.00347","-0.00347","2.13109"
"15.30000","1.31275","-0.00347","-0.00347","2.13663"
"15.40000","1.32050","-0.00346","-0.00346","2.14628"
"15.50000","1.32939","-0.00345","-0.00345","2.15863"
"15.60000","1.33813","-0.00344","-0.00344","2.16614"
"15.70000","1.34602","-0.00343","-0.00343","2.17264"
"15.80000","1.35410","-0.00342","-0.00342","2.18382"
"15.90000","1.36296","-0.00341","-0.00341","2.19383"
"16.00000","1.37118","-0.00341","-0.00341","2.19876"
"16.10000","1.37884","-0.00340","-0.00340","2.20610"
"16.20000","1.38742","-0.00339","-0.00339","2.21861"
"16.30000","1.39640","-0.00337","-0.00337","2.22737"
"16.40000","1.40448","-0.00337","-0.00337","2.23173"
"16.50000","1.41226","-0.00336","-0.00336","2.24062"
"16.60000","1.42102","-0.00335","-0.00335","2.25220"
"16.70000","1.42979","-0.00334","-0.00334","2.25798"
"16.80000","1.43742","-0.00334","-0.00334","2.26259"
"16.90000","1.44561","-0.00333","-0.00333","2.27403"
"17.00000","1.45468","-0.00331","-0.00331","2.28367"
"17.10000","1.46297","-0.00331","-0.00331","2.28752"
"17.20000","1.47062","-0.00330","-0.00330","2.29386"
"17.30000","1.47921","-0.00329","-0.00329","2.30487"
"17.40000","1.48807","-0.00328","-0.00328","2.31129"
"17.50000","1.49591","-0.00328","-0.00328","2.31457"
"17.60000","1.50383","-0.00326","-0.00326","2.32388"
"17.70000","1.51284","-0.00325","-0.00325","2.33441"
"17.80000","1.52140","-0.00324","-0.00324","2.33960"
"17.90000","1.52911","-0.00324","-0.00324","2.34520"
"18.00000","1.53734","-0.00323","-0.00323","2.35601"
"18.10000","1.54632","-0.00322","-0.00322","2.36274"
"18.20000","1.55449","-0.00321","-0.00321","2.36243"
"18.30000","1.56217","-0.00320","-0.00320","2.36745"
"18.40000","1.57094","-0.00320","-0.00320","2.37687"
"18.50000","1.57983","-0.00319","-0.00319","2.38246"
"18.60000","1.58776","-0.00319","-0.00319","2.38412"
"18.70000","1.59562","-0.00318","-0.00318","2.39181"
"18.80000","1.60454","-0.00317","-0.00317","2.40071"
"18.90000","1.61295","-0.00317","-0.00317","2.40476"
"19.00000","1.62069","-0.00316","-0.00316","2.40978"
"19.10000","1.62901","-0.00315","-0.00315","2.42150"
"19.20000","1.63796","-0.00313","-0.00313","2.43118"
"19.30000","1.64625","-0.00313","-0.00313","2.43543"
"19.40000","1.65396","-0.00312","-0.00312","2.44314"
"19.50000","1.66252","-0.00310","-0.00310","2.45502"
"19.60000","1.67147","-0.00309","-0.00309","2.46239"
"19.70000","1.67921","-0.00309","-0.00309","2.46585"
"19.80000","1.68717","-0.00307","-0.00307","2.47728"
"19.90000","1.69627","-0.00306","-0.00306","2.48945"
"20.00000","1.70483","-0.00305","-0.00305","2.49515"
"20.10000","1.71242","-0.00304","-0.00304","2.50117"
"20.20000","1.72077","-0.00303","-0.00303","2.51346"
"20.30000","1.72966","-0.00302","-0.00302","2.52275"
"20.40000","1.73770","-0.00301","-0.00301","2.52695"
"20.50000","1.74548","-0.00300","-0.00300","2.53666"
"20.60000","1.75437","-0.00298","-0.00298","2.54998"
"20.70000","1.76310","-0.00298","-0.00298","2.55734"
"20.80000","1.77088","-0.00296","-0.00296","2.56310"
"20.90000","1.77892","-0.00295","-0.00295","2.57509"
"21.00000","1.78787","-0.00294","-0.00294","2.58670"
"21.10000","1.79628","-0.00293","-0.00293","2.59178"
"21.20000","1.80391","-0.00292","-0.00292","2.59919"
"21.30000","1.81243","-0.00290","-0.00290","2.61213"
"21.40000","1.82144","-0.00289","-0.00289","2.62199"
"21.50000","1.82955","-0.00287","-0.00287","2.62676"
"21.60000","1.83729","-0.00286","-0.00286","2.63634"
"21.70000","1.84606","-0.00285","-0.00285","2.64887"
"21.80000","1.85468","-0.00284","-0.00284","2.65473"
"21.90000","1.86249","-0.00283","-0.00283","2.66005"
"22.00000","1.87065","-0.00281","-0.00281","2.67074"
"22.10000","1.87957","-0.00280","-0.00280","2.68148"
"22.20000","1.88807","-0.00278","-0.00278","2.68728"
"22.30000","1.89566","-0.00278","-0.00278","2.69449"
"22.40000","1.90401","-0.00276","-0.00276","2.70736"
"22.50000","1.91305","-0.00275","-0.00275","2.71736"
"22.60000","1.92107","-0.00274","-0.00274","2.72159"
"22.70000","1.92884","-0.00272","-0.00272","2.73118"
"22.80000","1.93773","-0.00271","-0.00271","2.74441"
"22.90000","1.94650","-0.00270","-0.00270","2.75092"
"23.00000","1.95421","-0.00269","-0.00269","2.75661"
"23.10000","1.96235","-0.00267","-0.00267","2.77007"
"23.20000","1.97127","-0.00266","-0.00266","2.78219"
"23.30000","1.97950","-0.00265","-0.00265","2.78792"
"23.40000","1.98715","-0.00263","-0.00263","2.79713"
"23.50000","1.99586","-0.00262","-0.00262","2.81161"
"23.60000","2.00481","-0.00261","-0.00261","2.82089"
"23.70000","2.01273","-0.00260","-0.00260","2.82661"
"23.80000","2.02057","-0.00258","-0.00258","2.83802"
"23.90000","2.02943","-0.00257","-0.00257","2.85164"
"24.00000","2.03799","-0.00256","-0.00256","2.85863"
"24.10000","2.04570","-0.00255","-0.00255","2.86564"
"24.20000","2.05402","-0.00254","-0.00254","2.87941"
"24.30000","2.06306","-0.00252","-0.00252","2.89099"
"24.40000","2.07131","-0.00251","-0.00251","2.89414"
"24.50000","2.07894","-0.00250","-0.00250","2.89558"
"24.60000","2.08756","-0.00249","-0.00249","2.90800"
"24.70000","2.09636","-0.00248","-0.00248","2.91560"
"24.80000","2.10434","-0.00246","-0.00246","2.92022"
"24.90000","2.11227","-0.00244","-0.00244","2.93098"
"25.00000","2.12113","-0.00242","-0.00242","2.94374"
"25.10000","2.12977","-0.00242","-0.00242","2.95114"
"25.20000","2.13746","-0.00240","-0.00240","2.95761"
"25.30000","2.14556","-0.00239","-0.00239","2.97016"
"25.40000","2.15463","-0.00237","-0.00237","2.97931"
"25.50000","2.16283","-0.00244","-0.00244","2.97279"
"25.60000","2.17048","-0.00256","-0.00256","2.96484"
"25.70000","2.17919","-0.00255","-0.00255","2.97371"
"25.80000","2.18820","-0.00254","-0.00254","2.97959"
"25.90000","2.19610","-0.00253","-0.00253","2.98189"
"26.00000","2.20396","-0.00254","-0.00254","2.98911"
"26.10000","2.21282","-0.00257","-0.00257","2.97270"
"26.20000","2.22123","-0.00265","-0.00265","2.95918"
"26.30000","2.22897","-0.00294","-0.00294","2.92398"
"26.40000","2.23747","-0.00304","-0.00304","2.89960"
"26.50000","2.24645","-0.00305","-0.00305","2.87842"
"26.60000","2.25447","-0.00307","-0.00307","2.85530"
"26.70000","2.26218","-0.00306","-0.00306","2.83523"
"26.80000","2.27092","-0.00305","-0.00305","2.83808"
"26.90000","2.27972","-0.00306","-0.00306","2.83916"
"27.00000","2.28758","-0.00308","-0.00308","2.83997"
"27.08100","2.29433","-0.02106","-0.02106","2.71468"
"27.18100","2.30322","-0.02743","-0.02743","2.61654"
"27.28100","2.31124","-0.02747","-0.02747","2.59830"
"27.38100","2.31907","-0.02744","-0.02744","2.59700"
"27.48100","2.32793","-0.02742","-0.02742","2.60290"
"27.58100","2.33643","-0.02740","-0.02740","2.60153"
"27.68100","2.34415","-0.02740","-0.02740","2.59410"
"27.78100","2.35243","-0.02741","-0.02741","2.55294"
"27.88100","2.36141","-0.02741","-0.02741","2.53404"
"27.98100","2.36976","-0.02743","-0.02743","2.51868"
"28.08100","2.37738","-0.02744","-0.02744","2.50420"
"28.18100","2.38588","-0.02745","-0.02745","2.49824"
"28.28100","2.39480","-0.02745","-0.02745","2.49239"
"28.38100","2.40267","-0.02745","-0.02745","2.48569"
"28.48100","2.41059","-0.02744","-0.02744","2.48945"
"28.58100","2.41954","-0.02743","-0.02743","2.49664"
"28.68100","2.42822","-0.02742","-0.02742","2.49868"
"28.78100","2.43584","-0.02742","-0.02742","2.50243"
"28.88100","2.44413","-0.02741","-0.02741","2.51449"
"28.98100","2.45311","-0.02740","-0.02740","2.52336"
"29.08100","2.46122","-0.02740","-0.02740","2.52693"
"29.18100","2.46890","-0.02739","-0.02739","2.53638"
"29.28100","2.47773","-0.02738","-0.02738","2.54998"
"29.38100","2.48650","-0.02737","-0.02737","2.55781"
"29.48100","2.49433","-0.02737","-0.02737","2.56363"
"29.58100","2.50235","-0.02735","-0.02735","2.57660"
"29.68100","2.51124","-0.02735","-0.02735","2.58883"
"29.78100","2.51974","-0.02734","-0.02734","2.59442"
"29.88100","2.52739","-0.02734","-0.02734","2.60154"
"29.98100","2.53577","-0.02732","-0.02732","2.61509"
"30.08100","2.54487","-0.02732","-0.02732","2.62571"
"30.18100","2.55303","-0.02731","-0.02731","2.63122"
"30.28100","2.56072","-0.02730","-0.02730","2.64059"
"30.38100","2.56940","-0.02730","-0.02730","2.65268"
"30.48100","2.57811","-0.02729","-0.02729","2.65963"
"30.58100","2.58600","-0.02730","-0.02730","2.66560"
"30.68100","2.59402","-0.02729","-0.02729","2.67809"
"30.78100","2.60297","-0.02727","-0.02727","2.69124"
"30.88100","2.61149","-0.02727","-0.02727","2.69827"
"30.98100","2.61909","-0.02727","-0.02727","2.70545"
"31.08100","2.62740","-0.02726","-0.02726","2.71955"
"31.18100","2.63648","-0.02725","-0.02725","2.73087"
"31.28100","2.64452","-0.02724","-0.02724","2.73561"
"31.38100","2.65224","-0.02724","-0.02724","2.74716"
"31.48100","2.66106","-0.02722","-0.02722","2.76206"
"31.58100","2.66992","-0.02721","-0.02721","2.77037"
"31.68100","2.67770","-0.02721","-0.02721","2.77615"
"31.78100","2.68577","-0.02720","-0.02720","2.78988"
"31.88100","2.69466","-0.02719","-0.02719","2.80203"
"31.98100","2.70295","-0.02719","-0.02719","2.80813"
"32.08100","2.71057","-0.02718","-0.02718","2.81765"
"32.18100","2.71925","-0.02717","-0.02717","2.83299"
"32.28100","2.72820","-0.02715","-0.02715","2.84356"
"32.38100","2.73613","-0.02715","-0.02715","2.84957"
"32.48100","2.74393","-0.02714","-0.02714","2.86178"
"32.58100","2.75270","-0.02713","-0.02713","2.87600"
"32.68100","2.76138","-0.02712","-0.02712","2.88401"
"32.78100","2.76922","-0.02711","-0.02711","2.89145"
"32.88100","2.77741","-0.02710","-0.02710","2.90562"
"32.98100","2.78645","-0.02709","-0.02709","2.91846"
"33.08100","2.79477","-0.02708","-0.02708","2.92476"
"33.18100","2.80239","-0.02708","-0.02708","2.93321"
"33.28100","2.81098","-0.02706","-0.02706","2.94779"
"33.38100","2.81981","-0.02706","-0.02706","2.95736"
"33.48100","2.82783","-0.02706","-0.02706","2.96344"
"33.58100","2.83566","-0.02705","-0.02705","2.97478"
"33.68100","2.84449","-0.02703","-0.02703","2.98867"
"33.78100","2.85323","-0.02703","-0.02703","2.99707"
"33.88100","2.86094","-0.02703","-0.02703","3.00283"
"33.98100","2.86902","-0.02702","-0.02702","3.01572"
"34.08100","2.87800","-0.02701","-0.02701","3.02749"
"34.18100","2.88629","-0.02701","-0.02701","3.03200"
"34.28100","2.89388","-0.02700","-0.02700","3.04073"
"34.38100","2.90259","-0.02699","-0.02699","3.05473"
"34.48100","2.91160","-0.02699","-0.02699","3.06286"
"34.58100","2.91955","-0.02698","-0.02698","3.06620"
"34.68100","2.92733","-0.02698","-0.02698","3.07639"
"34.78100","2.93622","-0.02697","-0.02697","3.08835"
"34.88100","2.94475","-0.02696","-0.02696","3.09375"
"34.98100","2.95243","-0.02696","-0.02696","3.10020"
"35.08100","2.96084","-0.02695","-0.02695","3.11375"
"35.18100","2.96982","-0.02694","-0.02694","3.12417"
"35.28100","2.97789","-0.02694","-0.02694","3.12820"
"35.38100","2.98558","-0.02693","-0.02693","3.13728"
"35.48100","2.99425","-0.02692","-0.02692","3.15090"
"35.58100","3.00308","-0.02691","-0.02691","3.15882"
"35.68100","3.01104","-0.02691","-0.02691","3.16362"
"35.78100","3.01899","-0.02690","-0.02690","3.17487"
"35.88100","3.02797","-0.02689","-0.02689","3.18732"
"35.98100","3.03653","-0.02688","-0.02688","3.19290"
"36.08100","3.04425","-0.02688","-0.02688","3.19845"
"36.18100","3.05253","-0.02687","-0.02687","3.21080"
"36.28100","3.06139","-0.02686","-0.02686","3.21998"
"36.38100","3.06959","-0.02686","-0.02686","3.22427"
"36.48100","3.07736","-0.02685","-0.02685","3.23298"
"36.58100","3.08604","-0.02684","-0.02684","3.24592"
"36.68100","3.09493","-0.02684","-0.02684","3.25368"
"36.78100","3.10277","-0.02683","-0.02683","3.25713"
"36.88100","3.11054","-0.02682","-0.02682","3.26711"
"36.98100","3.11952","-0.02682","-0.02682","3.27907"
"37.08100","3.12811","-0.02681","-0.02681","3.28363"
"37.18100","3.13570","-0.02681","-0.02681","3.28899"
"37.28100","3.14411","-0.02680","-0.02680","3.30204"
"37.38100","3.15321","-0.02679","-0.02679","3.31119"
"37.48100","3.16132","-0.02679","-0.02679","3.31365"
"37.58100","3.16897","-0.02678","-0.02678","3.32163"
"37.68100","3.17774","-0.02677","-0.02677","3.33311"
"37.78100","3.18645","-0.02677","-0.02677","3.33847"
"37.88100","3.19425","-0.02676","-0.02676","3.34185"
"37.98100","3.20236","-0.02675","-0.02675","3.35325"
"38.08100","3.21140","-0.02674","-0.02674","3.36363"
"38.18100","3.21972","-0.02674","-0.02674","3.36656"
"38.28100","3.22740","-0.02673","-0.02673","3.37235"
"38.38100","3.23578","-0.02673","-0.02673","3.38379"
"38.48100","3.24470","-0.02672","-0.02672","3.39140"
"38.58100","3.25277","-0.02672","-0.02672","3.39403"
"38.68100","3.26061","-0.02671","-0.02671","3.40265"
"38.78100","3.26953","-0.02670","-0.02670","3.41390"
"38.88100","3.27824","-0.02670","-0.02670","3.41839"
"38.98100","3.28604","-0.02670","-0.02670","3.42058"
"39.08100","3.29409","-0.02669","-0.02669","3.43014"
"39.18100","3.30301","-0.02668","-0.02668","3.43879"
"39.28100","3.31141","-0.02668","-0.02668","3.44206"
"39.38100","3.31907","-0.02667","-0.02667","3.44641"
"39.48100","3.32760","-0.02666","-0.02666","3.45716"
"39.58100","3.33652","-0.02666","-0.02666","3.46408"
"39.68100","3.34456","-0.02666","-0.02666","3.46477"
"39.78100","3.35225","-0.02666","-0.02666","3.47125"
"39.88100","3.36108","-0.02665","-0.02665","3.48170"
"39.98100","3.36984","-0.02664","-0.02664","3.48456"
"40.08100","3.37753","-0.02664","-0.02664","3.48653"
"40.18100","3.38566","-0.02664","-0.02664","3.49581"
"40.28100","3.39479","-0.02663","-0.02663","3.50478"
"40.38100","3.40311","-0.02663","-0.02663","3.50609"
"40.48100","3.41068","-0.02663","-0.02663","3.51037"
"40.58100","3.41926","-0.02662","-0.02662","3.52056"
"40.68100","3.42812","-0.02661","-0.02661","3.52574"
"40.78100","3.43605","-0.02661","-0.02661","3.52671"
"40.88100","3.44400","-0.02661","-0.02661","3.53539"
"40.98100","3.45295","-0.02660","-0.02660","3.54523"
"41.08100","3.46151","-0.02659","-0.02659","3.54786"
"41.18100","3.46920","-0.02659","-0.02659","3.55060"
"41.28100","3.47733","-0.02659","-0.02659","3.56061"
"41.38100","3.48634","-0.02658","-0.02658","3.56895"
"41.48100","3.49460","-0.02658","-0.02658","3.57127"
"41.58100","3.50225","-0.02657","-0.02657","3.57746"
"41.68100","3.51102","-0.02656","-0.02656","3.58970"
"41.78100","3.51988","-0.02656","-0.02656","3.59619"
"41.88100","3.52784","-0.02656","-0.02656","3.59882"
"41.98100","3.53570","-0.02655","-0.02655","3.60851"
"42.08100","3.54456","-0.02654","-0.02654","3.61899"
"42.18100","3.55312","-0.02654","-0.02654","3.62364"
"42.28100","3.56089","-0.02653","-0.02653","3.62779"
"42.38100","3.56912","-0.02653","-0.02653","3.63909"
"42.48100","3.57813","-0.02652","-0.02652","3.64920"
"42.58100","3.58636","-0.02652","-0.02652","3.65207"
"42.68100","3.59392","-0.02651","-0.02651","3.65867"
"42.78100","3.60257","-0.02650","-0.02650","3.67141"
"42.88100","3.61152","-0.02650","-0.02650","3.67775"
"42.98100","3.61941","-0.02650","-0.02650","3.68020"
"43.08100","3.62731","-0.02649","-0.02649","3.69005"
"43.18100","3.63632","-0.02648","-0.02648","3.70172"
"43.28100","3.64488","-0.02648","-0.02648","3.70524"
"43.38100","3.65238","-0.02647","-0.02647","3.70965"
"43.48100","3.66079","-0.02646","-0.02646","3.72196"
"43.58100","3.66974","-0.02645","-0.02645","3.73020"
"43.68100","3.67784","-0.02645","-0.02645","3.73381"
"43.78100","3.68559","-0.02645","-0.02645","3.74251"
"43.88100","3.69445","-0.02644","-0.02644","3.75530"
"43.98100","3.70322","-0.02643","-0.02643","3.76075"
"44.08100","3.71105","-0.02643","-0.02643","3.76439"
"44.18100","3.71895","-0.02643","-0.02643","3.77233"
"44.28100","3.72793","-0.02642","-0.02642","3.78265"
"44.38100","3.73636","-0.02641","-0.02641","3.78606"
"44.48100","3.74402","-0.02641","-0.02641","3.79161"
"44.58100","3.75254","-0.02640","-0.02640","3.80436"
"44.68100","3.76149","-0.02639","-0.02639","3.81295"
"44.78100","3.76957","-0.02639","-0.02639","3.81504"
"44.88100","3.77725","-0.02639","-0.02639","3.82326"
"44.98100","3.78602","-0.02638","-0.02638","3.83461"
"45.08100","3.79485","-0.02637","-0.02637","3.84079"
"45.18100","3.80278","-0.02637","-0.02637","3.84474"
"45.28100","3.81076","-0.02636","-0.02636","3.85441"
"45.38100","3.81968","-0.02636","-0.02636","3.86510"
"45.48100","3.82812","-0.02636","-0.02636","3.86826"
"45.58100","3.83565","-0.02635","-0.02635","3.87332"
"45.68100","3.84409","-0.02634","-0.02634","3.88628"
"45.78100","3.85319","-0.02634","-0.02634","3.89427"
"45.88100","3.86118","-0.02633","-0.02633","3.89680"
"45.98100","3.86892","-0.02632","-0.02632","3.90546"
"46.08100","3.87778","-0.02632","-0.02632","3.91869"
"46.18100","3.88658","-0.02631","-0.02631","3.92428"
"46.28100","3.89426","-0.02631","-0.02631","3.92769"
"46.38100","3.90237","-0.02630","-0.02630","3.93870"
"46.48100","3.91132","-0.02629","-0.02629","3.94941"
"46.58100","3.91961","-0.02629","-0.02629","3.95305"
"46.68100","3.92735","-0.02628","-0.02628","3.95989"
"46.78100","3.93600","-0.02627","-0.02627","3.97259"
"46.88100","3.94492","-0.02627","-0.02627","3.97939"
"46.98100","3.95278","-0.02627","-0.02627","3.98223"
"47.08100","3.96056","-0.02626","-0.02626","3.99142"
"47.18100","3.96948","-0.02625","-0.02625","4.00342"
"47.28100","3.97813","-0.02625","-0.02625","4.00845"
"47.38100","3.98590","-0.02624","-0.02624","4.01267"
"47.48100","3.99416","-0.02623","-0.02623","4.02447"
"47.58100","4.00314","-0.02623","-0.02623","4.03376"
"47.68100","4.01136","-0.02623","-0.02623","4.03681"
"47.78100","4.01899","-0.02623","-0.02623","4.04299"
"47.88100","4.02752","-0.02622","-0.02622","4.05416"
"47.98100","4.03647","-0.02622","-0.02622","4.06115"
"48.08100","4.04454","-0.02622","-0.02622","4.06458"
"48.18100","4.05238","-0.02621","-0.02621","4.07318"
"48.28100","4.06124","-0.02620","-0.02620","4.08452"
"48.38100","4.06994","-0.02619","-0.02619","4.08885"
"48.48100","4.07754","-0.02620","-0.02620","4.09116"
"48.58100","4.08561","-0.02619","-0.02619","4.10230"
"48.68100","4.09478","-0.02618","-0.02618","4.11222"
"48.78100","4.10300","-0.02618","-0.02618","4.11426"
"48.88100","4.11066","-0.02618","-0.02618","4.12143"
"48.98100","4.11927","-0.02616","-0.02616","4.13419"
"49.08100","4.12825","-0.02617","-0.02617","4.13985"
"49.18100","4.13606","-0.02618","-0.02618","4.14020"
"49.28100","4.14392","-0.02617","-0.02617","4.14899"
"49.38100","4.15290","-0.02616","-0.02616","4.15963"
"49.48100","4.16146","-0.02616","-0.02616","4.16323"
"49.58100","4.16912","-0.02616","-0.02616","4.16755"
"49.68100","4.17752","-0.02616","-0.02616","4.17930"
"49.78100","4.18650","-0.02615","-0.02615","4.18699"
"49.88100","4.19461","-0.02615","-0.02615","4.18886"
"49.98100","4.20223","-0.02614","-0.02614","4.19556"
"50.08100","4.21097","-0.02614","-0.02614","4.20757"
"50.18100","4.21980","-0.02613","-0.02613","4.21279"
"50.28100","4.22767","-0.02613","-0.02613","4.21489"
"50.38100","4.23574","-0.02613","-0.02613","4.22691"
"50.48100","4.24472","-0.02612","-0.02612","4.24144"
"50.58100","4.25313","-0.02611","-0.02611","4.24806"
"50.68100","4.26069","-0.02611","-0.02611","4.25481"
"50.78100","4.26907","-0.02610","-0.02610","4.26928"
"50.88100","4.27808","-0.02608","-0.02608","4.28049"
"50.98100","4.28631","-0.02608","-0.02608","4.28513"
"51.08100","4.29408","-0.02607","-0.02607","4.29543"
"51.18100","4.30273","-0.02606","-0.02606","4.30967"
"51.28100","4.31162","-0.02605","-0.02605","4.31826"
"51.38100","4.31930","-0.02605","-0.02605","4.32246"
"51.48100","4.32723","-0.02604","-0.02604","4.33585"
"51.58100","4.33636","-0.02602","-0.02602","4.35048"
"51.68100","4.34477","-0.02602","-0.02602","4.35528"
"51.78100","4.35239","-0.02601","-0.02601","4.36300"
"51.88100","4.36077","-0.02599","-0.02599","4.37866"
"51.98100","4.36984","-0.02598","-0.02598","4.38997"
"52.08100","4.37785","-0.02597","-0.02597","4.39449"
"52.18100","4.38557","-0.02596","-0.02596","4.40585"
"52.28100","4.39446","-0.02595","-0.02595","4.42077"
"52.38100","4.40314","-0.02594","-0.02594","4.42762"
"52.48100","4.41091","-0.02594","-0.02594","4.43366"
"52.58100","4.41911","-0.02593","-0.02593","4.44831"
"52.68100","4.42815","-0.02592","-0.02592","4.46155"
"52.78100","4.43637","-0.02591","-0.02591","4.46645"
"52.88100","4.44397","-0.02591","-0.02591","4.47478"
"52.98100","4.45247","-0.02589","-0.02589","4.49020"
"53.08100","4.46144","-0.02588","-0.02588","4.50065"
"53.18100","4.46952","-0.02587","-0.02587","4.50627"
"53.28100","4.47739","-0.02586","-0.02586","4.51843"
"53.38100","4.48621","-0.02584","-0.02584","4.53336"
"53.48100","4.49483","-0.02583","-0.02583","4.54019"
"53.58100","4.50249","-0.02583","-0.02583","4.54541"
"53.68100","4.51068","-0.02582","-0.02582","4.55959"
"53.78100","4.51969","-0.02581","-0.02581","4.57296"
"53.88100","4.52807","-0.02580","-0.02580","4.57873"
"53.98100","4.53575","-0.02579","-0.02579","4.58725"
"54.08100","4.54425","-0.02579","-0.02579","4.60188"
"54.18100","4.55323","-0.02578","-0.02578","4.61139"
"54.28100","4.56122","-0.02577","-0.02577","4.61530"
"54.38100","4.56887","-0.02577","-0.02577","4.62552"
"54.48100","4.57782","-0.02575","-0.02575","4.64079"
"54.58100","4.58650","-0.02575","-0.02575","4.64708"
"54.68100","4.59418","-0.02574","-0.02574","4.65301"
"54.78100","4.60241","-0.02572","-0.02572","4.66869"
"54.88100","4.61145","-0.02571","-0.02571","4.68074"
"54.98100","4.61959","-0.02570","-0.02570","4.68371"
"55.08100","4.62721","-0.02569","-0.02569","4.69267"
"55.18100","4.63592","-0.02568","-0.02568","4.70745"
"55.28100","4.64484","-0.02567","-0.02567","4.71674"
"55.38100","4.65279","-0.02567","-0.02567","4.72179"
"55.48100","4.66072","-0.02566","-0.02566","4.73403"
"55.58100","4.66964","-0.02565","-0.02565","4.74729"
"55.68100","4.67811","-0.02564","-0.02564","4.75174"
"55.78100","4.68576","-0.02564","-0.02564","4.75605"
"55.88100","4.69408","-0.02563","-0.02563","4.77073"
"55.98100","4.70309","-0.02562","-0.02562","4.78153"
"56.08100","4.71128","-0.02562","-0.02562","4.78581"
"56.18100","4.71906","-0.02561","-0.02561","4.79583"
"56.28100","4.72777","-0.02559","-0.02559","4.80878"
"56.38100","4.73654","-0.02559","-0.02559","4.81555"
"56.48100","4.74431","-0.02558","-0.02558","4.81834"
"56.58100","4.75227","-0.02557","-0.02557","4.83073"
"56.68100","4.76122","-0.02555","-0.02555","4.84477"
"56.78100","4.76977","-0.02554","-0.02554","4.85120"
"56.88100","4.77755","-0.02554","-0.02554","4.85692"
"56.98100","4.78584","-0.02553","-0.02553","4.87131"
"57.08100","4.79485","-0.02551","-0.02551","4.88281"
"57.18100","4.80295","-0.02551","-0.02551","4.88587"
"57.28100","4.81052","-0.02550","-0.02550","4.89482"
"57.38100","4.81931","-0.02549","-0.02549","4.91051"
"57.48100","4.82826","-0.02548","-0.02548","4.91931"
"57.58100","4.83610","-0.02547","-0.02547","4.92433"
"57.68100","4.84396","-0.02547","-0.02547","4.93616"
"57.78100","4.85297","-0.02545","-0.02545","4.94936"
"57.88100","4.86138","-0.02545","-0.02545","4.95452"
"57.98100","4.86898","-0.02543","-0.02543","4.96287"
"58.08100","4.87747","-0.02542","-0.02542","4.97765"
"58.18100","4.88648","-0.02549","-0.02549","4.97544"
"58.28100","4.89453","-0.02550","-0.02550","4.97869"
"58.38100","4.90230","-0.02550","-0.02550","4.98898"
"58.48100","4.91116","-0.02549","-0.02549","5.00311"
"58.58100","4.91987","-0.02549","-0.02549","5.00991"
"58.68100","4.92762","-0.02548","-0.02548","5.01395"
"58.78100","4.93566","-0.02547","-0.02547","5.02714"
"58.88100","4.94461","-0.02546","-0.02546","5.03914"
"58.98100","4.95305","-0.02545","-0.02545","5.04342"
"59.08100","4.96085","-0.02544","-0.02544","5.05130"
"59.18100","4.96932","-0.02543","-0.02543","5.06478"
"59.28100","4.97815","-0.02542","-0.02542","5.07293"
"59.38100","4.98611","-0.02542","-0.02542","5.07448"
"59.48100","4.99391","-0.02541","-0.02541","5.08431"
"59.58100","5.00277","-0.02540","-0.02540","5.09837"
"59.68100","5.01154","-0.02539","-0.02539","5.10490"
"59.78100","5.01934","-0.02538","-0.02538","5.10869"
"59.88100","5.02742","-0.02537","-0.02537","5.12116"
"59.98100","5.03637","-0.02536","-0.02536","5.13345"
"60.08100","5.04472","-0.02536","-0.02536","5.13717"
"60.18100","5.05222","-0.02535","-0.02535","5.14413"
"60.28100","5.06087","-0.02534","-0.02534","5.16000"
"60.38100","5.06988","-0.02533","-0.02533","5.16976"
"60.48100","5.07786","-0.02532","-0.02532","5.17388"
"60.58100","5.08564","-0.02531","-0.02531","5.18552"
"60.68100","5.09459","-0.02530","-0.02530","5.20132"
"60.78100","5.10315","-0.02529","-0.02529","5.20761"
"60.88100","5.11074","-0.02529","-0.02529","5.21333"
"60.98100","5.11903","-0.02527","-0.02527","5.22862"
"61.08100","5.12810","-0.02527","-0.02527","5.24118"
"61.18100","5.13638","-0.02526","-0.02526","5.24661"
"61.28100","5.14401","-0.02525","-0.02525","5.25666"
"61.38100","5.15269","-0.02524","-0.02524","5.27322"
"61.48100","5.16145","-0.02524","-0.02524","5.28196"
"61.58100","5.16938","-0.02524","-0.02524","5.28658"
"61.68100","5.17725","-0.02523","-0.02523","5.30034"
"61.78100","5.18623","-0.02522","-0.02522","5.31553"
"61.88100","5.19478","-0.02521","-0.02521","5.32255"
"61.98100","5.20262","-0.02520","-0.02520","5.33067"
"62.08100","5.21081","-0.02519","-0.02519","5.34481"
"62.18100","5.21976","-0.02518","-0.02518","5.35586"
"62.28100","5.22793","-0.02518","-0.02518","5.36021"
"62.38100","5.23561","-0.02517","-0.02517","5.36953"
"62.48100","5.24429","-0.02515","-0.02515","5.38456"
"62.58100","5.25318","-0.02515","-0.02515","5.39311"
"62.68100","5.26117","-0.02515","-0.02515","5.39552"
"62.78100","5.26909","-0.02514","-0.02514","5.40673"
"62.88100","5.27792","-0.02512","-0.02512","5.41974"
"62.98100","5.28645","-0.02512","-0.02512","5.42381"
"63.08100","5.29395","-0.02512","-0.02512","5.42762"
"63.18100","5.30236","-0.02510","-0.02510","5.44231"
"63.28100","5.31149","-0.02509","-0.02509","5.45279"
"63.38100","5.31972","-0.02509","-0.02509","5.45552"
"63.48100","5.32731","-0.02508","-0.02508","5.46355"
"63.58100","5.33608","-0.02506","-0.02506","5.47822"
"63.68100","5.34482","-0.02506","-0.02506","5.48391"
"63.78100","5.35256","-0.02506","-0.02506","5.48702"
"63.88100","5.36064","-0.02505","-0.02505","5.49945"
"63.98100","5.36968","-0.02503","-0.02503","5.51194"
"64.08100","5.37812","-0.02503","-0.02503","5.51668"
"64.18100","5.38571","-0.02502","-0.02502","5.52300"
"64.28100","5.39415","-0.02501","-0.02501","5.53678"
"64.38100","5.40313","-0.02500","-0.02500","5.54639"
"64.48100","5.41124","-0.02500","-0.02500","5.54979"
"64.58100","5.41892","-0.02499","-0.02499","5.55939"
"64.68100","5.42772","-0.02498","-0.02498","5.57373"
"64.78100","5.43652","-0.02497","-0.02497","5.58083"
"64.88100","5.44447","-0.02497","-0.02497","5.58537"
"64.98100","5.45246","-0.02497","-0.02497","5.59817"
"65.08100","5.46135","-0.02496","-0.02496","5.61097"
"65.18100","5.46966","-0.02496","-0.02496","5.61697"
"65.28100","5.47732","-0.02495","-0.02495","5.62593"
"65.38100","5.48585","-0.02494","-0.02494","5.64331"
"65.48100","5.49480","-0.02493","-0.02493","5.65604"
"65.58100","5.50299","-0.02493","-0.02493","5.66283"
"65.68100","5.51068","-0.02492","-0.02492","5.67510"
"65.78100","5.51939","-0.02490","-0.02490","5.69252"
"65.88100","5.52815","-0.02489","-0.02489","5.70106"
"65.98100","5.53587","-0.02489","-0.02489","5.70762"
"66.08100","5.54400","-0.02488","-0.02488","5.72406"
"66.18100","5.55304","-0.02487","-0.02487","5.73896"
"66.28100","5.56148","-0.02486","-0.02486","5.74517"
"66.38100","5.56902","-0.02486","-0.02486","5.75332"
"66.48100","5.57757","-0.02485","-0.02485","5.77034"
"66.58100","5.58646","-0.02484","-0.02484","5.78057"
"66.68100","5.59442","-0.02483","-0.02483","5.78594"
"66.78100","5.60225","-0.02482","-0.02482","5.79993"
"66.88100","5.61120","-0.02481","-0.02481","5.81588"
"66.98100","5.61985","-0.02481","-0.02481","5.82349"
"67.08100","5.62757","-0.02480","-0.02480","5.83054"
"67.18100","5.63567","-0.02479","-0.02479","5.84567"
"67.28100","5.64468","-0.02478","-0.02478","5.85820"
"67.38100","5.65291","-0.02478","-0.02478","5.86287"
"67.48100","5.66059","-0.02477","-0.02477","5.87232"
"67.58100","5.66927","-0.02476","-0.02476","5.88726"
"67.68100","5.67825","-0.02476","-0.02476","5.89566"
"67.78100","5.68627","-0.02476","-0.02476","5.89982"
"67.88100","5.69407","-0.02476","-0.02476","5.91026"
"67.98100","5.70287","-0.02475","-0.02475","5.92126"
"68.08100","5.71143","-0.02475","-0.02475","5.92529"
"68.18100","5.71920","-0.02475","-0.02475","5.93091"
"68.28100","5.72743","-0.02475","-0.02475","5.94142"
"68.38100","5.73638","-0.02474","-0.02474","5.94973"
"68.48100","5.74473","-0.02474","-0.02474","5.95375"
"68.58100","5.75232","-0.02473","-0.02473","5.96025"
"68.68100","5.76091","-0.02472","-0.02472","5.97427"
"68.78100","5.76983","-0.02471","-0.02471","5.98106"
"68.88100","5.77769","-0.02471","-0.02471","5.98246"
"68.98100","5.78559","-0.02470","-0.02470","5.99357"
"69.08100","5.79454","-0.02469","-0.02469","6.00676"
"69.18100","5.80325","-0.02468","-0.02468","6.01138"
"69.28100","5.81090","-0.02468","-0.02468","6.01500"
"69.38100","5.81916","-0.02467","-0.02467","6.02915"
"69.48100","5.82808","-0.02466","-0.02466","6.03814"
"69.58100","5.83615","-0.02466","-0.02466","6.04037"
"69.68100","5.84390","-0.02465","-0.02465","6.04923"
"69.78100","5.85276","-0.02464","-0.02464","6.06403"
"69.88100","5.86156","-0.02464","-0.02464","6.07063"
"69.98100","5.86936","-0.02463","-0.02463","6.07325"
"70.08100","5.87732","-0.02463","-0.02463","6.07742"
"70.18100","5.88624","-0.02464","-0.02464","6.07773"
"70.28100","5.89470","-0.02465","-0.02465","6.07832"
"70.38100","5.90245","-0.02464","-0.02464","6.08171"
"70.48100","5.91080","-0.02464","-0.02464","6.09329"
"70.58100","5.91984","-0.02464","-0.02464","6.10107"
"70.68100","5.92797","-0.02464","-0.02464","6.10182"
"70.78100","5.93575","-0.02464","-0.02464","6.10628"
"70.88100","5.94439","-0.02464","-0.02464","6.11638"
"70.98100","5.95310","-0.02463","-0.02463","6.11983"
"71.08100","5.96100","-0.02463","-0.02463","6.12183"
"71.18100","5.96901","-0.02462","-0.02462","6.13178"
"71.28100","5.97793","-0.02462","-0.02462","6.14060"
"71.38100","5.98652","-0.02462","-0.02462","6.13900"
"71.48100","5.99417","-0.02463","-0.02463","6.13927"
"71.58100","6.00240","-0.02462","-0.02462","6.14624"
"71.68100","6.01141","-0.02462","-0.02462","6.15035"
"71.74700","6.01602","-0.02476","-0.02476","6.01852"
"71.76600","6.01801","-0.02503","-0.02503","5.88985"
"71.83500","6.02413","-0.02525","-0.02525","5.76464"
"71.93500","6.03275","-0.02531","-0.02531","5.70406"
"72.03500","6.04034","-0.02534","-0.02534","5.66633"
"72.13500","6.04860","-0.02538","-0.02538","5.63712"
"72.23500","6.05764","-0.02540","-0.02540","5.61284"
"72.33500","6.06574","-0.02543","-0.02543","5.58364"
"72.43500","6.07343","-0.02547","-0.02547","5.55121"
"72.53500","6.08220","-0.02550","-0.02550","5.53312"
"72.63500","6.09100","-0.02556","-0.02556","5.47680"
"72.73500","6.09889","-0.02561","-0.02561","5.43701"
"72.83500","6.10688","-0.02563","-0.02563","5.41042"
"72.93500","6.11589","-0.02567","-0.02567","5.37732"
"73.03000","6.12384","-0.02579","-0.02579","5.25100"
"73.13000","6.13143","-0.02590","-0.02590","5.13651"
"73.23000","6.13996","-0.02598","-0.02598","5.05886"
"73.33000","6.14888","-0.02605","-0.02605","4.99054"
"73.43000","6.15690","-0.02614","-0.02614","4.89041"
"73.53000","6.16485","-0.02622","-0.02622","4.81360"
"73.63000","6.17368","-0.02628","-0.02628","4.74632"
"73.73000","6.18230","-0.02636","-0.02636","4.63132"
"73.81400","6.18839","-0.02645","-0.02645","4.50619"
"73.90900","6.19674","-0.02652","-0.02652","4.38004"
"73.99900","6.20463","-0.02660","-0.02660","4.25402"
"74.09900","6.21241","-0.02670","-0.02670","4.13519"
"74.19900","6.22075","-0.02676","-0.02676","4.04103"
"74.29900","6.22964","-0.02684","-0.02684","3.95807"
"74.39900","6.23781","-0.02690","-0.02690","3.87713"
"74.49900","6.24540","-0.02695","-0.02695","3.80807"
"74.59900","6.25417","-0.02698","-0.02698","3.75250"
"74.69900","6.26300","-0.02703","-0.02703","3.69446"
"74.79900","6.27080","-0.02707","-0.02707","3.63695"
"74.89900","6.27882","-0.02711","-0.02711","3.59246"
"74.99900","6.28786","-0.02714","-0.02714","3.55523"
"75.09900","6.29633","-0.02717","-0.02717","3.51475"
"75.19900","6.30392","-0.02719","-0.02719","3.48046"
"75.29900","6.31236","-0.02721","-0.02721","3.45486"
"75.39900","6.32128","-0.02723","-0.02723","3.42764"
"75.49900","6.32929","-0.02725","-0.02725","3.39748"
"75.59900","6.33716","-0.02727","-0.02727","3.37588"
"75.69900","6.34608","-0.02728","-0.02728","3.35849"
"75.79900","6.35473","-0.02730","-0.02730","3.33434"
"75.89900","6.36244","-0.02732","-0.02732","3.31089"
"75.99900","6.37046","-0.02733","-0.02733","3.29595"
"76.09900","6.37947","-0.02733","-0.02733","3.28134"
"76.19900","6.38781","-0.02735","-0.02735","3.25974"
"76.29900","6.39550","-0.02737","-0.02737","3.24205"
"76.39900","6.40412","-0.02737","-0.02737","3.23048"
"76.49900","6.41304","-0.02738","-0.02738","3.21402"
"76.59900","6.42105","-0.02740","-0.02740","3.19275"
"76.69900","6.42880","-0.02741","-0.02741","3.17791"
"76.79900","6.43766","-0.02742","-0.02742","3.16568"
"76.89900","6.44636","-0.02744","-0.02744","3.14715"
"76.99900","6.45417","-0.02745","-0.02745","3.12515"
"77.09900","6.46228","-0.02747","-0.02747","3.11061"
"77.19900","6.47126","-0.02748","-0.02748","3.09459"
"77.29900","6.47963","-0.02751","-0.02751","3.07183"
"77.39900","6.48714","-0.02752","-0.02752","3.05073"
"77.49900","6.49566","-0.02753","-0.02753","3.03745"
"77.59900","6.50464","-0.02755","-0.02755","3.01839"
"77.69900","6.51260","-0.02756","-0.02756","2.99590"
"77.79900","6.52046","-0.02757","-0.02757","2.98120"
"77.89900","6.52938","-0.02759","-0.02759","2.96908"
"77.99900","6.53803","-0.02760","-0.02760","2.94827"
"78.07800","6.54376","-0.02762","-0.02762","2.93177"